[2025-04-22T18:26:09.525+0000] {task_context_logger.py:104} ERROR - Executor reports task instance <TaskInstance: preprocessing_pipeline.run_preprocessing manual__2025-04-22T18:26:01.638833+00:00 [queued]> finished (failed) although the task says it's queued. (Info: None) Was the task killed externally?
